<?xml version="1.0" encoding="utf-8"?>
<!-- =================================================================================== -->
<!-- |    This document was autogenerated by xacro from /home/led/catkin_ws/src/cob_pushing/robots/cart/cart.urdf.xarco | -->
<!-- |    EDITING THIS FILE BY HAND IS NOT RECOMMENDED                                 | -->
<!-- =================================================================================== -->
<robot name="continuous_pendulum" xmlns:body="http://playerstage.sourceforge.net/gazebo/xmlschema/#body" xmlns:controller="http://playerstage.sourceforge.net/gazebo/xmlschema/#controller" xmlns:gazebo="http://playerstage.sourceforge.net/gazebo/xmlschema/#gz" xmlns:geom="http://playerstage.sourceforge.net/gazebo/xmlschema/#geom" xmlns:interface="http://playerstage.sourceforge.net/gazebo/xmlschema/#interface" xmlns:joint="http://playerstage.sourceforge.net/gazebo/xmlschema/#joint" xmlns:model="http://playerstage.sourceforge.net/gazebo/xmlschema/#model" xmlns:physics="http://playerstage.sourceforge.net/gazebo/xmlschema/#physics" xmlns:renderable="http://playerstage.sourceforge.net/gazebo/xmlschema/#renderable" xmlns:rendering="http://playerstage.sourceforge.net/gazebo/xmlschema/#rendering" xmlns:sensor="http://playerstage.sourceforge.net/gazebo/xmlschema/#sensor" xmlns:xi="http://www.w3.org/2001/XInclude">
  <!-- Base link of the robot (we attach cart frame to this in tf using fake_cart_joint_state_publisher)-->
  <link name="base">
    <inertial>
      <mass value="0.1"/>
      <inertia ixx="0.01" ixy="0.0" ixz="0.0" iyy="0.01" iyz="0.0" izz="0.01"/>
    </inertial>
  </link>
  <!--
       name = shelf name ["top"] *this is also the frame name in tf
       parent = parent link name ["base"]
       color = an rgba tuple "155 155 155 0.7"
       length = a scalar
       width = a scalar
       thickness = a scalar
       origin = a block representing the orign to insert
      -->
  <joint name="bottom_joint" type="fixed">
    <origin rpy="0 0 0" xyz="0.07 0.0 0.16"/>
    <parent link="base"/>
    <child link="bottom"/>
  </joint>
  <link name="bottom">
    <inertial>
      <mass value="4"/>
      <origin xyz="0 0 0"/>
      <inertia ixx="0.1" ixy="0.0" ixz="0.0" iyy="0.1" iyz="0.0" izz="0.1"/>
    </inertial>
    <visual>
      <origin rpy="0 0 0" xyz="0 0 0"/>
      <geometry>
        <box size="0.7 0.42 0.06"/>
      </geometry>
      <material name="0 0 0 0.7">
        <!--Dumb to use for a name, but whatever-->
        <color rgba="0 0 0 0.7"/>
      </material>
    </visual>
    <collision>
      <origin rpy="0 0 0" xyz="0 0 0"/>
      <geometry>
        <box size="0.7 0.42 0.06"/>
      </geometry>
    </collision>
  </link>
  <gazebo reference="bottom">
    <mu1>10</mu1>
    <mu2>10</mu2>
    <material>Gazebo/Blue</material>
    <turnGravityOff>false</turnGravityOff>
  </gazebo>
  <!--
       name = shelf name ["top"] *this is also the frame name in tf
       parent = parent link name ["base"]
       color = an rgba tuple "155 155 155 0.7"
       length = a scalar
       width = a scalar
       thickness = a scalar
       origin = a block representing the orign to insert
      -->
  <joint name="top_joint" type="fixed">
    <origin rpy="0 0 0" xyz="0 0 0.3"/>
    <parent link="bottom"/>
    <child link="top"/>
  </joint>
  <link name="top">
    <inertial>
      <mass value="1"/>
      <origin xyz="0 0 0"/>
      <inertia ixx="0.1" ixy="0.0" ixz="0.0" iyy="0.1" iyz="0.0" izz="0.1"/>
    </inertial>
    <visual>
      <origin rpy="0 0 0" xyz="0 0 0"/>
      <geometry>
        <box size="0.7 0.42 0.06"/>
      </geometry>
      <material name="0 0 0 0.7">
        <!--Dumb to use for a name, but whatever-->
        <color rgba="0 0 0 0.7"/>
      </material>
    </visual>
    <collision>
      <origin rpy="0 0 0" xyz="0 0 0"/>
      <geometry>
        <box size="0.7 0.42 0.06"/>
      </geometry>
    </collision>
  </link>
  <gazebo reference="top">
    <mu1>10</mu1>
    <mu2>10</mu2>
    <material>Gazebo/Blue</material>
    <turnGravityOff>false</turnGravityOff>
  </gazebo>
  <!--
       prefix = caster name ["front_left"]
       color = an rgba tuple "155 155 155 0.7"
       top_offset = a scalar
       *origin = an origin block containing xyz="" and rpy="" fields
      -->
  <joint name="front_left_caster" type="continuous">
    <origin rpy="0 0 0" xyz="0.325 -0.185 0"/>
    <parent link="bottom"/>
    <child link="front_left_caster"/>
    <axis xyz="0 0 1"/>
  </joint>
  <link name="front_left_caster">
    <inertial>
      <mass value="0.1"/>
      <origin xyz="0 0 -0.055"/>
      <inertia ixx="0.0001" ixy="0.0" ixz="0.0" iyy="0.0001" iyz="0.0" izz="0.0001"/>
    </inertial>
    <visual>
      <origin rpy="0 0 0" xyz="0 0 -0.055"/>
      <geometry>
        <cylinder length="0.05" radius="0.025"/>
      </geometry>
      <material name="0 0 0 0.7">
        <!--Dumb to use for a name, but whatever-->
        <color rgba="0 0 0 0.7"/>
      </material>
    </visual>
    <collision>
      <origin rpy="0 0 0" xyz="0 0 -0.055"/>
      <geometry>
        <cylinder length="0.05" radius="0.025"/>
      </geometry>
    </collision>
  </link>
  <gazebo reference="front_left_caster">
    <mu1>0</mu1>
    <mu2>0</mu2>
    <material>Gazebo/Red</material>
    <turnGravityOff>false</turnGravityOff>
  </gazebo>
  <!--
       prefix = wheel name ["front_left"]
       color = an rgba tuple "155 155 155 0.7"
       offset = a scalar
       radius = a scalar
       width = a scalar
      -->
  <joint name="front_left_wheel" type="continuous">
    <origin rpy="0 0 0" xyz="-0.05 0 -0.1"/>
    <parent link="front_left_caster"/>
    <child link="front_left_wheel"/>
    <axis xyz="0 1 0"/>
  </joint>
  <link name="front_left_wheel">
    <inertial>
      <mass value="0.1"/>
      <origin xyz="0 0 0"/>
      <inertia ixx="0.001" ixy="0.0" ixz="0.0" iyy="0.001" iyz="0.0" izz="0.001"/>
    </inertial>
    <visual>
      <origin rpy="1.57079632679 0 0" xyz="0 0 0"/>
      <geometry>
        <cylinder length="0.02" radius="0.05"/>
      </geometry>
      <material name="0.8 0.8 0.8 0.7">
        <!--Dumb to use for a name, but whatever-->
        <color rgba="0.8 0.8 0.8 0.7"/>
      </material>
    </visual>
    <collision>
      <origin rpy="1.57079632679 0 0" xyz="0 0 0"/>
      <geometry>
        <cylinder length="0.02" radius="0.05"/>
      </geometry>
    </collision>
  </link>
  <gazebo reference="front_left_wheel">
    <dampingFactor>0.01</dampingFactor>
    <mu1>1</mu1>
    <mu2>1</mu2>
    <material>Gazebo/Green</material>
    <turnGravityOff>false</turnGravityOff>
  </gazebo>
  <!--
       prefix = caster name ["front_left"]
       color = an rgba tuple "155 155 155 0.7"
       top_offset = a scalar
       *origin = an origin block containing xyz="" and rpy="" fields
      -->
  <joint name="front_right_caster" type="continuous">
    <origin rpy="0 0 0" xyz="0.325 0.185 0"/>
    <parent link="bottom"/>
    <child link="front_right_caster"/>
    <axis xyz="0 0 1"/>
  </joint>
  <link name="front_right_caster">
    <inertial>
      <mass value="0.1"/>
      <origin xyz="0 0 -0.055"/>
      <inertia ixx="0.0001" ixy="0.0" ixz="0.0" iyy="0.0001" iyz="0.0" izz="0.0001"/>
    </inertial>
    <visual>
      <origin rpy="0 0 0" xyz="0 0 -0.055"/>
      <geometry>
        <cylinder length="0.05" radius="0.025"/>
      </geometry>
      <material name="0 0 0 0.7">
        <!--Dumb to use for a name, but whatever-->
        <color rgba="0 0 0 0.7"/>
      </material>
    </visual>
    <collision>
      <origin rpy="0 0 0" xyz="0 0 -0.055"/>
      <geometry>
        <cylinder length="0.05" radius="0.025"/>
      </geometry>
    </collision>
  </link>
  <gazebo reference="front_right_caster">
    <mu1>0</mu1>
    <mu2>0</mu2>
    <material>Gazebo/Red</material>
    <turnGravityOff>false</turnGravityOff>
  </gazebo>
  <!--
       prefix = wheel name ["front_left"]
       color = an rgba tuple "155 155 155 0.7"
       offset = a scalar
       radius = a scalar
       width = a scalar
      -->
  <joint name="front_right_wheel" type="continuous">
    <origin rpy="0 0 0" xyz="-0.05 0 -0.1"/>
    <parent link="front_right_caster"/>
    <child link="front_right_wheel"/>
    <axis xyz="0 1 0"/>
  </joint>
  <link name="front_right_wheel">
    <inertial>
      <mass value="0.1"/>
      <origin xyz="0 0 0"/>
      <inertia ixx="0.001" ixy="0.0" ixz="0.0" iyy="0.001" iyz="0.0" izz="0.001"/>
    </inertial>
    <visual>
      <origin rpy="1.57079632679 0 0" xyz="0 0 0"/>
      <geometry>
        <cylinder length="0.02" radius="0.05"/>
      </geometry>
      <material name="0.8 0.8 0.8 0.7">
        <!--Dumb to use for a name, but whatever-->
        <color rgba="0.8 0.8 0.8 0.7"/>
      </material>
    </visual>
    <collision>
      <origin rpy="1.57079632679 0 0" xyz="0 0 0"/>
      <geometry>
        <cylinder length="0.02" radius="0.05"/>
      </geometry>
    </collision>
  </link>
  <gazebo reference="front_right_wheel">
    <dampingFactor>0.01</dampingFactor>
    <mu1>1</mu1>
    <mu2>1</mu2>
    <material>Gazebo/Green</material>
    <turnGravityOff>false</turnGravityOff>
  </gazebo>
  <!--
       prefix = caster name ["front_left"]
       color = an rgba tuple "155 155 155 0.7"
       top_offset = a scalar
       *origin = an origin block containing xyz="" and rpy="" fields
      -->
  <joint name="back_left_caster" type="continuous">
    <origin rpy="0 0 0" xyz="-0.325 -0.185 0"/>
    <parent link="bottom"/>
    <child link="back_left_caster"/>
    <axis xyz="0 0 1"/>
  </joint>
  <link name="back_left_caster">
    <inertial>
      <mass value="0.1"/>
      <origin xyz="0 0 -0.055"/>
      <inertia ixx="0.0001" ixy="0.0" ixz="0.0" iyy="0.0001" iyz="0.0" izz="0.0001"/>
    </inertial>
    <visual>
      <origin rpy="0 0 0" xyz="0 0 -0.055"/>
      <geometry>
        <cylinder length="0.05" radius="0.025"/>
      </geometry>
      <material name="0 0 0 0.7">
        <!--Dumb to use for a name, but whatever-->
        <color rgba="0 0 0 0.7"/>
      </material>
    </visual>
    <collision>
      <origin rpy="0 0 0" xyz="0 0 -0.055"/>
      <geometry>
        <cylinder length="0.05" radius="0.025"/>
      </geometry>
    </collision>
  </link>
  <gazebo reference="back_left_caster">
    <mu1>0</mu1>
    <mu2>0</mu2>
    <material>Gazebo/Red</material>
    <turnGravityOff>false</turnGravityOff>
  </gazebo>
  <!--
       prefix = wheel name ["front_left"]
       color = an rgba tuple "155 155 155 0.7"
       offset = a scalar
       radius = a scalar
       width = a scalar
      -->
  <joint name="back_left_wheel" type="continuous">
    <origin rpy="0 0 0" xyz="-0.05 0 -0.1"/>
    <parent link="back_left_caster"/>
    <child link="back_left_wheel"/>
    <axis xyz="0 1 0"/>
  </joint>
  <link name="back_left_wheel">
    <inertial>
      <mass value="0.1"/>
      <origin xyz="0 0 0"/>
      <inertia ixx="0.001" ixy="0.0" ixz="0.0" iyy="0.001" iyz="0.0" izz="0.001"/>
    </inertial>
    <visual>
      <origin rpy="1.57079632679 0 0" xyz="0 0 0"/>
      <geometry>
        <cylinder length="0.02" radius="0.05"/>
      </geometry>
      <material name="0.8 0.8 0.8 0.7">
        <!--Dumb to use for a name, but whatever-->
        <color rgba="0.8 0.8 0.8 0.7"/>
      </material>
    </visual>
    <collision>
      <origin rpy="1.57079632679 0 0" xyz="0 0 0"/>
      <geometry>
        <cylinder length="0.02" radius="0.05"/>
      </geometry>
    </collision>
  </link>
  <gazebo reference="back_left_wheel">
    <dampingFactor>0.01</dampingFactor>
    <mu1>1</mu1>
    <mu2>1</mu2>
    <material>Gazebo/Green</material>
    <turnGravityOff>false</turnGravityOff>
  </gazebo>
  <!--
       prefix = caster name ["front_left"]
       color = an rgba tuple "155 155 155 0.7"
       top_offset = a scalar
       *origin = an origin block containing xyz="" and rpy="" fields
      -->
  <joint name="back_right_caster" type="continuous">
    <origin rpy="0 0 0" xyz="-0.325 0.185 0"/>
    <parent link="bottom"/>
    <child link="back_right_caster"/>
    <axis xyz="0 0 1"/>
  </joint>
  <link name="back_right_caster">
    <inertial>
      <mass value="0.1"/>
      <origin xyz="0 0 -0.055"/>
      <inertia ixx="0.0001" ixy="0.0" ixz="0.0" iyy="0.0001" iyz="0.0" izz="0.0001"/>
    </inertial>
    <visual>
      <origin rpy="0 0 0" xyz="0 0 -0.055"/>
      <geometry>
        <cylinder length="0.05" radius="0.025"/>
      </geometry>
      <material name="0 0 0 0.7">
        <!--Dumb to use for a name, but whatever-->
        <color rgba="0 0 0 0.7"/>
      </material>
    </visual>
    <collision>
      <origin rpy="0 0 0" xyz="0 0 -0.055"/>
      <geometry>
        <cylinder length="0.05" radius="0.025"/>
      </geometry>
    </collision>
  </link>
  <gazebo reference="back_right_caster">
    <mu1>0</mu1>
    <mu2>0</mu2>
    <material>Gazebo/Red</material>
    <turnGravityOff>false</turnGravityOff>
  </gazebo>
  <!--
       prefix = wheel name ["front_left"]
       color = an rgba tuple "155 155 155 0.7"
       offset = a scalar
       radius = a scalar
       width = a scalar
      -->
  <joint name="back_right_wheel" type="continuous">
    <origin rpy="0 0 0" xyz="-0.05 0 -0.1"/>
    <parent link="back_right_caster"/>
    <child link="back_right_wheel"/>
    <axis xyz="0 1 0"/>
  </joint>
  <link name="back_right_wheel">
    <inertial>
      <mass value="0.1"/>
      <origin xyz="0 0 0"/>
      <inertia ixx="0.001" ixy="0.0" ixz="0.0" iyy="0.001" iyz="0.0" izz="0.001"/>
    </inertial>
    <visual>
      <origin rpy="1.57079632679 0 0" xyz="0 0 0"/>
      <geometry>
        <cylinder length="0.02" radius="0.05"/>
      </geometry>
      <material name="0.8 0.8 0.8 0.7">
        <!--Dumb to use for a name, but whatever-->
        <color rgba="0.8 0.8 0.8 0.7"/>
      </material>
    </visual>
    <collision>
      <origin rpy="1.57079632679 0 0" xyz="0 0 0"/>
      <geometry>
        <cylinder length="0.02" radius="0.05"/>
      </geometry>
    </collision>
  </link>
  <gazebo reference="back_right_wheel">
    <dampingFactor>0.01</dampingFactor>
    <mu1>1</mu1>
    <mu2>1</mu2>
    <material>Gazebo/Green</material>
    <turnGravityOff>false</turnGravityOff>
  </gazebo>
  <joint name="front_left_leg_joint" type="fixed">
    <origin rpy="0 0 0" xyz="0 0 0.15"/>
    <parent link="front_left_caster"/>
    <child link="front_left_leg"/>
  </joint>
  <link name="front_left_leg">
    <inertial>
      <mass value="0.1"/>
      <origin xyz="0 0 0"/>
      <inertia ixx="0.01" ixy="0.0" ixz="0.0" iyy="0.01" iyz="0.0" izz="0.01"/>
    </inertial>
    <visual>
      <origin rpy="0 0 0" xyz="0 0 0"/>
      <geometry>
        <cylinder length="0.24" radius="0.02"/>
      </geometry>
      <material name="0.8 0.8 0.8 0.7">
        <color rgba="0.8 0.8 0.8 0.7"/>
      </material>
    </visual>
    <collision>
      <origin rpy="0 0 0" xyz="0 0 0"/>
      <geometry>
        <cylinder length="0.24" radius="0.02"/>
      </geometry>
    </collision>
  </link>
  <gazebo reference="front_left_leg">
    <mu1>10</mu1>
    <mu2>10</mu2>
    <material>Gazebo/BumpyMetal</material>
    <turnGravityOff>false</turnGravityOff>
  </gazebo>
  <joint name="front_right_leg_joint" type="fixed">
    <origin rpy="0 0 0" xyz="0 0 0.15"/>
    <parent link="front_right_caster"/>
    <child link="front_right_leg"/>
  </joint>
  <link name="front_right_leg">
    <inertial>
      <mass value="0.1"/>
      <origin xyz="0 0 0"/>
      <inertia ixx="0.01" ixy="0.0" ixz="0.0" iyy="0.01" iyz="0.0" izz="0.01"/>
    </inertial>
    <visual>
      <origin rpy="0 0 0" xyz="0 0 0"/>
      <geometry>
        <cylinder length="0.24" radius="0.02"/>
      </geometry>
      <material name="0.8 0.8 0.8 0.7">
        <color rgba="0.8 0.8 0.8 0.7"/>
      </material>
    </visual>
    <collision>
      <origin rpy="0 0 0" xyz="0 0 0"/>
      <geometry>
        <cylinder length="0.24" radius="0.02"/>
      </geometry>
    </collision>
  </link>
  <gazebo reference="front_right_leg">
    <mu1>10</mu1>
    <mu2>10</mu2>
    <material>Gazebo/BumpyMetal</material>
    <turnGravityOff>false</turnGravityOff>
  </gazebo>
  <joint name="back_left_leg_joint" type="fixed">
    <origin rpy="0 0 0" xyz="0 0 0.33"/>
    <parent link="back_left_caster"/>
    <child link="back_left_leg"/>
  </joint>
  <link name="back_left_leg">
    <inertial>
      <mass value="0.1"/>
      <origin xyz="0 0 0"/>
      <inertia ixx="0.01" ixy="0.0" ixz="0.0" iyy="0.01" iyz="0.0" izz="0.01"/>
    </inertial>
    <visual>
      <origin rpy="0 0 0" xyz="0 0 0"/>
      <geometry>
        <cylinder length="0.6" radius="0.02"/>
      </geometry>
      <material name="0.8 0.8 0.8 0.7">
        <color rgba="0.8 0.8 0.8 0.7"/>
      </material>
    </visual>
    <collision>
      <origin rpy="0 0 0" xyz="0 0 0"/>
      <geometry>
        <cylinder length="0.6" radius="0.02"/>
      </geometry>
    </collision>
  </link>
  <gazebo reference="back_left_leg">
    <mu1>10</mu1>
    <mu2>10</mu2>
    <material>Gazebo/BumpyMetal</material>
    <turnGravityOff>false</turnGravityOff>
  </gazebo>
  <joint name="back_right_leg_joint" type="fixed">
    <origin rpy="0 0 0" xyz="0 0 0.33"/>
    <parent link="back_right_caster"/>
    <child link="back_right_leg"/>
  </joint>
  <link name="back_right_leg">
    <inertial>
      <mass value="0.1"/>
      <origin xyz="0 0 0"/>
      <inertia ixx="0.01" ixy="0.0" ixz="0.0" iyy="0.01" iyz="0.0" izz="0.01"/>
    </inertial>
    <visual>
      <origin rpy="0 0 0" xyz="0 0 0"/>
      <geometry>
        <cylinder length="0.6" radius="0.02"/>
      </geometry>
      <material name="0.8 0.8 0.8 0.7">
        <color rgba="0.8 0.8 0.8 0.7"/>
      </material>
    </visual>
    <collision>
      <origin rpy="0 0 0" xyz="0 0 0"/>
      <geometry>
        <cylinder length="0.6" radius="0.02"/>
      </geometry>
    </collision>
  </link>
  <gazebo reference="back_right_leg">
    <mu1>10</mu1>
    <mu2>10</mu2>
    <material>Gazebo/BumpyMetal</material>
    <turnGravityOff>false</turnGravityOff>
  </gazebo>
  <joint name="handle_joint" type="fixed">
    <origin rpy="1.57079632679 0 0" xyz="-0.43 0 0.43"/>
    <parent link="top"/>
    <child link="handle"/>
  </joint>
  <link name="handle">
    <inertial>
      <mass value="0.1"/>
      <origin xyz="0 0 0"/>
      <inertia ixx="0.01" ixy="0.0" ixz="0.0" iyy="0.01" iyz="0.0" izz="0.01"/>
    </inertial>
    <visual>
      <origin rpy="0 0 0" xyz="0 0 0"/>
      <geometry>
        <cylinder length="0.4" radius="0.02"/>
      </geometry>
      <material name="0 0 0 0.7">
        <color rgba="0 0 0 0.7"/>
      </material>
    </visual>
    <collision>
      <origin rpy="0 0 0" xyz="0 0 0"/>
      <geometry>
        <cylinder length="0.4" radius="0.02"/>
      </geometry>
    </collision>
  </link>
  <gazebo reference="handle">
    <mu1>10</mu1>
    <mu2>10</mu2>
    <material>Gazebo/BumpyMetal</material>
    <turnGravityOff>false</turnGravityOff>
  </gazebo>
  <joint name="handle_rmt_joint" type="fixed">
    <origin rpy="0.785398163397 1.57079632679 0" xyz="0.05 -0.05 0.18"/>
    <parent link="handle"/>
    <child link="handle_rmt"/>
  </joint>
  <link name="handle_rmt">
    <inertial>
      <mass value="0.1"/>
      <origin xyz="0 0 0"/>
      <inertia ixx="0.01" ixy="0.0" ixz="0.0" iyy="0.01" iyz="0.0" izz="0.01"/>
    </inertial>
    <visual>
      <origin rpy="0 0 0" xyz="0 0 0"/>
      <geometry>
        <cylinder length="0.16" radius="0.02"/>
      </geometry>
      <material name="0 0 0 0.7">
        <color rgba="0 0 0 0.7"/>
      </material>
    </visual>
    <collision>
      <origin rpy="0 0 0" xyz="0 0 0"/>
      <geometry>
        <cylinder length="0.16" radius="0.02"/>
      </geometry>
    </collision>
  </link>
  <gazebo reference="handle_rmt">
    <mu1>10</mu1>
    <mu2>10</mu2>
    <material>Gazebo/BumpyMetal</material>
    <turnGravityOff>false</turnGravityOff>
  </gazebo>
  <joint name="handle_lmt_joint" type="fixed">
    <origin rpy="0.785398163397 1.57079632679 0" xyz="0.05 -0.05 -0.18"/>
    <parent link="handle"/>
    <child link="handle_lmt"/>
  </joint>
  <link name="handle_lmt">
    <inertial>
      <mass value="0.1"/>
      <origin xyz="0 0 0"/>
      <inertia ixx="0.01" ixy="0.0" ixz="0.0" iyy="0.01" iyz="0.0" izz="0.01"/>
    </inertial>
    <visual>
      <origin rpy="0 0 0" xyz="0 0 0"/>
      <geometry>
        <cylinder length="0.16" radius="0.02"/>
      </geometry>
      <material name="0 0 0 0.7">
        <color rgba="0 0 0 0.7"/>
      </material>
    </visual>
    <collision>
      <origin rpy="0 0 0" xyz="0 0 0"/>
      <geometry>
        <cylinder length="0.16" radius="0.02"/>
      </geometry>
    </collision>
  </link>
  <gazebo reference="handle_lmt">
    <mu1>10</mu1>
    <mu2>10</mu2>
    <material>Gazebo/BumpyMetal</material>
    <turnGravityOff>false</turnGravityOff>
  </gazebo>
</robot>
